Workbook
Name FolderPath: Sheet1!$J$1

Sheet GetPath
A1: GetPath
A2: C:\Users\Tomaz\Documents\ITA\PRJ-22\Tomav\

Sheet Sheet1
B1: Pesquisa 1 | C1: Pesquisa 2 | D1: Pesquisa 3 | E1: Pesquisa 4 | F1: Pesquisa 1 | G1: Pesquisa 2 | H1: Pesquisa 3 | I1: Pesquisa 4 | J1: {=LEFT(CELL("filename",J1),FIND("[",CELL("filename",J1))-1)} -> C:\Users\Tomaz\Documents\ITA\PRJ-22\Tomav\
A2: Parâmetro | B2: Mínimo | C2: Mínimo2 | D2: Mínimo3 | E2: Mínimo4 | F2: Máximo | G2: Máximo5 | H2: Máximo6 | I2: Máximo7 | J2: Tomav Atual | K2: Pesquisa 1 | L2: Pesquisa 2 | M2: Pesquisa 3 | N2: Pesquisa 4 | O2: Pontuação
A3: tcr_w | B3: 0.12 | C3: 0.13 | D3: 0.11 | E3: 0.12 | F3: 0.16 | G3: 0.16 | H3: 0.16 | I3: 0.16 | J3: =IF(LEFT(A3,5)="sweep", _xlfn.XLOOKUP("inputs_"&A3, tomav!$A$2:$A$222, tomav!$B$2:$B$222) * (180/PI()), _xlfn.XLOOKUP("inputs_"&A3, tomav!$A$2:$A$222, tomav!$B$2:$B$222)) -> 0.175 | K3: =IF(AND($J3>=B3,$J3<=F3),"OK","NÃO OK") -> NÃO OK | L3: =IF(AND($J3>=C3,$J3<=G3),"OK","NÃO OK") -> NÃO OK | M3: =IF(AND($J3>=D3,$J3<=H3),"OK","NÃO OK") -> NÃO OK | N3: =IF(AND($J3>=E3,$J3<=I3),"OK","NÃO OK") -> NÃO OK | O3: =EXACT(K3, "OK")+EXACT(L3, "OK")+EXACT(M3, "OK")+EXACT(N3, "OK") -> 0
A4: Cht | B4: 0.7 | C4: 0.9 | D4: 0.85 | E4: 0.9 | F4: 1.15 | G4: 1.2 | H4: 1.2 | I4: 1.2 | J4: =IF(LEFT(A4,5)="sweep", _xlfn.XLOOKUP("inputs_"&A4, tomav!$A$2:$A$222, tomav!$B$2:$B$222) * (180/PI()), _xlfn.XLOOKUP("inputs_"&A4, tomav!$A$2:$A$222, tomav!$B$2:$B$222)) -> 0.85 | K4: =IF(AND($J4>=B4,$J4<=F4),"OK","NÃO OK") -> OK | L4: =IF(AND($J4>=C4,$J4<=G4),"OK","NÃO OK") -> NÃO OK | M4: =IF(AND($J4>=D4,$J4<=H4),"OK","NÃO OK") -> OK | N4: =IF(AND($J4>=E4,$J4<=I4),"OK","NÃO OK") -> NÃO OK | O4: =EXACT(K4, "OK")+EXACT(L4, "OK")+EXACT(M4, "OK")+EXACT(N4, "OK") -> 2
A5: AR_h | B5: 3.4 | C5: 3.5 | D5: 4 | E5: 3.4 | F5: 6.5 | G5: 5.5 | H5: 5.5 | I5: 6.1 | J5: =IF(LEFT(A5,5)="sweep", _xlfn.XLOOKUP("inputs_"&A5, tomav!$A$2:$A$222, tomav!$B$2:$B$222) * (180/PI()), _xlfn.XLOOKUP("inputs_"&A5, tomav!$A$2:$A$222, tomav!$B$2:$B$222)) -> 4 | K5: =IF(AND($J5>=B5,$J5<=F5),"OK","NÃO OK") -> OK | L5: =IF(AND($J5>=C5,$J5<=G5),"OK","NÃO OK") -> OK | M5: =IF(AND($J5>=D5,$J5<=H5),"OK","NÃO OK") -> OK | N5: =IF(AND($J5>=E5,$J5<=I5),"OK","NÃO OK") -> OK | O5: =EXACT(K5, "OK")+EXACT(L5, "OK")+EXACT(M5, "OK")+EXACT(N5, "OK") -> 4
A6: sweep_h | B6: 30 | C6: 35 | D6: 30 | E6: 30 | F6: 45 | G6: 40 | H6: 40 | I6: 45 | J6: =IF(LEFT(A6,5)="sweep", _xlfn.XLOOKUP("inputs_"&A6, tomav!$A$2:$A$222, tomav!$B$2:$B$222) * (180/PI()), _xlfn.XLOOKUP("inputs_"&A6, tomav!$A$2:$A$222, tomav!$B$2:$B$222)) -> 40 | K6: =IF(AND($J6>=B6,$J6<=F6),"OK","NÃO OK") -> OK | L6: =IF(AND($J6>=C6,$J6<=G6),"OK","NÃO OK") -> OK | M6: =IF(AND($J6>=D6,$J6<=H6),"OK","NÃO OK") -> OK | N6: =IF(AND($J6>=E6,$J6<=I6),"OK","NÃO OK") -> OK | O6: =EXACT(K6, "OK")+EXACT(L6, "OK")+EXACT(M6, "OK")+EXACT(N6, "OK") -> 4
A7: taper_v | B7: 0.25 | C7: 0.3 | D7: 0.25 | E7: 0.3 | F7: 0.8 | G7: 0.75 | H7: 0.5 | I7: 0.6 | J7: =IF(LEFT(A7,5)="sweep", _xlfn.XLOOKUP("inputs_"&A7, tomav!$A$2:$A$222, tomav!$B$2:$B$222) * (180/PI()), _xlfn.XLOOKUP("inputs_"&A7, tomav!$A$2:$A$222, tomav!$B$2:$B$222)) -> 0.35 | K7: =IF(AND($J7>=B7,$J7<=F7),"OK","NÃO OK") -> OK | L7: =IF(AND($J7>=C7,$J7<=G7),"OK","NÃO OK") -> OK | M7: =IF(AND($J7>=D7,$J7<=H7),"OK","NÃO OK") -> OK | N7: =IF(AND($J7>=E7,$J7<=I7),"OK","NÃO OK") -> OK | O7: =EXACT(K7, "OK")+EXACT(L7, "OK")+EXACT(M7, "OK")+EXACT(N7, "OK") -> 4
A8: sweep_v | B8: 35 | C8: 35 | D8: 35 | E8: 35 | F8: 55 | G8: 45 | H8: 45 | I8: 55 | J8: =IF(LEFT(A8,5)="sweep", _xlfn.XLOOKUP("inputs_"&A8, tomav!$A$2:$A$222, tomav!$B$2:$B$222) * (180/PI()), _xlfn.XLOOKUP("inputs_"&A8, tomav!$A$2:$A$222, tomav!$B$2:$B$222)) -> 42 | K8: =IF(AND($J8>=B8,$J8<=F8),"OK","NÃO OK") -> OK | L8: =IF(AND($J8>=C8,$J8<=G8),"OK","NÃO OK") -> OK | M8: =IF(AND($J8>=D8,$J8<=H8),"OK","NÃO OK") -> OK | N8: =IF(AND($J8>=E8,$J8<=I8),"OK","NÃO OK") -> OK | O8: =EXACT(K8, "OK")+EXACT(L8, "OK")+EXACT(M8, "OK")+EXACT(N8, "OK") -> 4
A9: tcr_v | B9: 0.1 | C9: 0.1 | D9: 0.09 | E9: 0.09 | F9: 0.16 | G9: 0.12 | H9: 0.12 | I9: 0.12 | J9: =IF(LEFT(A9,5)="sweep", _xlfn.XLOOKUP("inputs_"&A9, tomav!$A$2:$A$222, tomav!$B$2:$B$222) * (180/PI()), _xlfn.XLOOKUP("inputs_"&A9, tomav!$A$2:$A$222, tomav!$B$2:$B$222)) -> 0.095 | K9: =IF(AND($J9>=B9,$J9<=F9),"OK","NÃO OK") -> NÃO OK | L9: =IF(AND($J9>=C9,$J9<=G9),"OK","NÃO OK") -> NÃO OK | M9: =IF(AND($J9>=D9,$J9<=H9),"OK","NÃO OK") -> OK | N9: =IF(AND($J9>=E9,$J9<=I9),"OK","NÃO OK") -> OK | O9: =EXACT(K9, "OK")+EXACT(L9, "OK")+EXACT(M9, "OK")+EXACT(N9, "OK") -> 2
A10: taper_h | B10: 0.25 | C10: 0.3 | D10: 0.2 | E10: 0.25 | F10: 0.65 | G10: 0.6 | H10: 0.4 | I10: 0.65 | J10: =IF(LEFT(A10,5)="sweep", _xlfn.XLOOKUP("inputs_"&A10, tomav!$A$2:$A$222, tomav!$B$2:$B$222) * (180/PI()), _xlfn.XLOOKUP("inputs_"&A10, tomav!$A$2:$A$222, tomav!$B$2:$B$222)) -> 0.35 | K10: =IF(AND($J10>=B10,$J10<=F10),"OK","NÃO OK") -> OK | L10: =IF(AND($J10>=C10,$J10<=G10),"OK","NÃO OK") -> OK | M10: =IF(AND($J10>=D10,$J10<=H10),"OK","NÃO OK") -> OK | N10: =IF(AND($J10>=E10,$J10<=I10),"OK","NÃO OK") -> OK | O10: =EXACT(K10, "OK")+EXACT(L10, "OK")+EXACT(M10, "OK")+EXACT(N10, "OK") -> 4
A11: AR_v | B11: 1.2 | C11: 1.2 | D11: 1 | E11: 1.3 | F11: 2.6 | G11: 2 | H11: 2 | I11: 2 | J11: =IF(LEFT(A11,5)="sweep", _xlfn.XLOOKUP("inputs_"&A11, tomav!$A$2:$A$222, tomav!$B$2:$B$222) * (180/PI()), _xlfn.XLOOKUP("inputs_"&A11, tomav!$A$2:$A$222, tomav!$B$2:$B$222)) -> 1.5 | K11: =IF(AND($J11>=B11,$J11<=F11),"OK","NÃO OK") -> OK | L11: =IF(AND($J11>=C11,$J11<=G11),"OK","NÃO OK") -> OK | M11: =IF(AND($J11>=D11,$J11<=H11),"OK","NÃO OK") -> OK | N11: =IF(AND($J11>=E11,$J11<=I11),"OK","NÃO OK") -> OK | O11: =EXACT(K11, "OK")+EXACT(L11, "OK")+EXACT(M11, "OK")+EXACT(N11, "OK") -> 4
A12: AR_w | B12: 6.9 | C12: 8 | D12: 7 | E12: 7 | F12: 11 | G12: 12 | H12: 11 | I12: 11 | J12: =IF(LEFT(A12,5)="sweep", _xlfn.XLOOKUP("inputs_"&A12, tomav!$A$2:$A$222, tomav!$B$2:$B$222) * (180/PI()), _xlfn.XLOOKUP("inputs_"&A12, tomav!$A$2:$A$222, tomav!$B$2:$B$222)) -> 10.5 | K12: =IF(AND($J12>=B12,$J12<=F12),"OK","NÃO OK") -> OK | L12: =IF(AND($J12>=C12,$J12<=G12),"OK","NÃO OK") -> OK | M12: =IF(AND($J12>=D12,$J12<=H12),"OK","NÃO OK") -> OK | N12: =IF(AND($J12>=E12,$J12<=I12),"OK","NÃO OK") -> OK | O12: =EXACT(K12, "OK")+EXACT(L12, "OK")+EXACT(M12, "OK")+EXACT(N12, "OK") -> 4
A13: taper_w | B13: 0.15 | C13: 0.14 | D13: 0.14 | E13: 0.15 | F13: 0.35 | G13: 0.3 | H13: 0.35 | I13: 0.35 | J13: =IF(LEFT(A13,5)="sweep", _xlfn.XLOOKUP("inputs_"&A13, tomav!$A$2:$A$222, tomav!$B$2:$B$222) * (180/PI()), _xlfn.XLOOKUP("inputs_"&A13, tomav!$A$2:$A$222, tomav!$B$2:$B$222)) -> 0.17 | K13: =IF(AND($J13>=B13,$J13<=F13),"OK","NÃO OK") -> OK | L13: =IF(AND($J13>=C13,$J13<=G13),"OK","NÃO OK") -> OK | M13: =IF(AND($J13>=D13,$J13<=H13),"OK","NÃO OK") -> OK | N13: =IF(AND($J13>=E13,$J13<=I13),"OK","NÃO OK") -> OK | O13: =EXACT(K13, "OK")+EXACT(L13, "OK")+EXACT(M13, "OK")+EXACT(N13, "OK") -> 4
A14: sweep_w | B14: 28 | C14: 28 | D14: 25 | E14: 25 | F14: 38 | G14: 35 | H14: 38 | I14: 40 | J14: =IF(LEFT(A14,5)="sweep", _xlfn.XLOOKUP("inputs_"&A14, tomav!$A$2:$A$222, tomav!$B$2:$B$222) * (180/PI()), _xlfn.XLOOKUP("inputs_"&A14, tomav!$A$2:$A$222, tomav!$B$2:$B$222)) -> 35.05 | K14: =IF(AND($J14>=B14,$J14<=F14),"OK","NÃO OK") -> OK | L14: =IF(AND($J14>=C14,$J14<=G14),"OK","NÃO OK") -> NÃO OK | M14: =IF(AND($J14>=D14,$J14<=H14),"OK","NÃO OK") -> OK | N14: =IF(AND($J14>=E14,$J14<=I14),"OK","NÃO OK") -> OK | O14: =EXACT(K14, "OK")+EXACT(L14, "OK")+EXACT(M14, "OK")+EXACT(N14, "OK") -> 3
... A21: b_flap_b_wing | B21: 0.6 | C21: 0.55 | D21: 0.55 | E21: 0.5 | F21: 0.85 | G21: 0.75 | H21: 0.75 | I21: 0.8 | J21: =IF(LEFT(A21,5)="sweep", _xlfn.XLOOKUP("inputs_"&A21, tomav!$A$2:$A$222, tomav!$B$2:$B$222) * (180/PI()), _xlfn.XLOOKUP("inputs_"&A21, tomav!$A$2:$A$222, tomav!$B$2:$B$222)) -> 0.63 | K21: =IF(AND($J21>=B21,$J21<=F21),"OK","NÃO OK") -> OK | L21: =IF(AND($J21>=C21,$J21<=G21),"OK","NÃO OK") -> OK | M21: =IF(AND($J21>=D21,$J21<=H21),"OK","NÃO OK") -> OK | N21: =IF(AND($J21>=E21,$J21<=I21),"OK","NÃO OK") -> OK | O21: =EXACT(K21, "OK")+EXACT(L21, "OK")+EXACT(M21, "OK")+EXACT(N21, "OK") -> 4

Sheet tomav
A1: Column1 | B1: Column2
A2: inputs_delta_xr_w | B2: -5.1
A3: inputs_type
A4: inputs_S_w | B4: 300
A5: inputs_AR_w | B5: 10.5
A6: inputs_taper_w | B6: 0.17
A7: inputs_sweep_w | B7: 0.6117379
A8: inputs_dihedral_w | B8: 0.087266463
A9: inputs_xr_w | B9: 16.9
A10: inputs_zr_w | B10: -1.85
A11: inputs_tcr_w | B11: 0.175
A12: inputs_tct_w | B12: 0.08
A13: inputs_Cht | B13: 0.85
A14: inputs_Lc_h | B14: 4.282546
A15: inputs_AR_h | B15: 4
... A51: inputs_k_korn | B51: 0.95
A52: inputs_flap_type
A53: inputs_slat_type
A54: inputs_c_flap_c_wing | B54: 0.33
A55: inputs_b_flap_b_wing | B55: 0.63
A56: inputs_c_slat_c_wing | B56: 0
A57: inputs_b_slat_b_wing | B57: 0
A58: inputs_c_ail_c_wing | B58: 0.3
A59: inputs_b_ail_b_wing | B59: 0.32
A60: inputs_h_ground | B60: 10.668
A61: inputs_k_exc_drag | B61: 0.03
A62: inputs_winglet
A63: inputs_altitude_takeoff | B63: 0
A64: inputs_distance_takeoff | B64: 2900
A65: inputs_deltaISA_takeoff | B65: 0
A66: inputs_altitude_landing | B66: 0
A67: inputs_distance_landing | B67: 2900
A68: inputs_deltaISA_landing | B68: 0
A69: inputs_MLW_frac | B69: 0.73928571
A70: inputs_altitude_cruise | B70: 9875.52
A71: inputs_Mach_cruise | B71: 0.85
A72: inputs_range_cruise | B72: 14816000
A73: inputs_altitude_maxcruise | B73: 9448.8
A74: inputs_Mach_maxcruise | B74: 0.9
... A89: inputs_W0_guess | B89: 2415727.7
...
